Workbook

Sheet 6. P&L Summary
A1: COMPANY Y — PROFIT & LOSS SUMMARY
A2: Formula: Revenue − Project Costs = Gross Profit → Gross Profit − Overhead = Net Profit
A4: Description | B4: Ref | C4: Project A ($) | D4: Project B ($) | E4: Project C ($) | F4: TOTAL ($)
A6: Client Payment (Revenue) | B6: Income | C6: ='3. Project — A'!B4 -> 0 | D6: ='4. Project — B'!B4 -> 0 | E6: ='5. Project — C'!B4 -> 0 | F6: =C6+D6+E6 -> 0
A7: − Project Direct Costs | B7: Costs | C7: ='3. Project — A'!B5 -> 0 | D7: ='4. Project — B'!B5 -> 0 | E7: ='5. Project — C'!B5 -> 0 | F7: =C7+D7+E7 -> 0
A8: GROSS PROFIT | C8: =C6-C7 -> 0 | D8: =D6-D7 -> 0 | E8: =E6-E7 -> 0 | F8: =F6-F7 -> 0
A10: MONTHLY OVERHEAD
A11: Utilities | B11: OH | C11: ='1. Company Overhead'!C13 -> 0 | D11: ='1. Company Overhead'!C13 -> 0 | E11: ='1. Company Overhead'!C13 -> 0 | F11: =C11 -> 0
A12: Payroll | B12: OH | C12: =#REF! -> #REF! | D12: =#REF! -> #REF! | E12: =#REF! -> #REF! | F12: =C12 -> #REF!
A13: Operations | B13: OH | C13: ='1. Company Overhead'!C24 -> 0 | D13: ='1. Company Overhead'!C24 -> 0 | E13: ='1. Company Overhead'!C24 -> 0 | F13: =C13 -> 0
A14: Total Overhead | C14: =C11 -> 0 | D14: =C11 -> 0 | E14: =C11 -> 0 | F14: =SUM(F11:F13) -> #REF!
A16: NET PROFIT | C16: =C8-C14 -> 0 | D16: =D8-D14 -> 0 | E16: =E8-E14 -> 0 | F16: =F8-F14 -> #REF!
A17: Net Profit Margin % | B17: % | C17: =IF(C6>0,C16/C6,0) -> 0 | D17: =IF(D6>0,D16/D6,0) -> 0 | E17: =IF(E6>0,E16/E6,0) -> 0 | F17: =IF(F6>0,F16/F6,0) -> 0

Sheet 1. Company Overhead
A1: COMPANY Y — MONTHLY OVERHEAD EXPENSES
A2: Update blue cells with your actual amounts
A4: A. OFFICE & UTILITIES
A5: Expense Item | B5: Description / Notes | C5: Monthly Amount ($)
A6: Office Rent | B6: Monthly office/studio payment | C6: 0
A7: Electricity | B7: Power bills | C7: 0
A8: Water | B8: Water bills | C8: 0
A9: Internet / WiFi | B9: Office internet | C9: 0
A10: Office Cleaning | B10: Cleaning materials / services | C10: 0
A11: Office Supplies | B11: Papers, pens, printing | C11: 0
A12: Refreshment | B12: Tea, Milk ,Sugar and Coffee | C12: 0
A13: Utilities Sub-total | C13: =SUM(C6:C12) -> 0
A15: B. COMPANY OPERATIONS
A16: Expense Item | B16: Description / Notes | C16: Monthly Amount ($)
A17: Marketing | B17: Facebook ads, banners, promotions | C17: 0
A18: Software Subscriptions | B18: AutoCAD, SketchUp, Adobe etc. | C18: 0
A19: Transportation / Fuel | B19: Office car fuel | C19: 0
A20: Maintenance | B20: Laptop, printer repair | C20: 0
A21: Bank Charges | B21: Transfer fees, bank fees | C21: 0
A22: Taxes & Licenses | B22: Government fees | C22: 0
A23: Other Operations | C23: 0
A24: Operations Sub-total | C24: =SUM(C17:C23) -> 0
A26: TOTAL MONTHLY OVERHEAD | C26: =C13+#REF!+C24 -> #REF!

Sheet Payroll
A1: SALARY PAYROLL
A2: No | B2: Name | C2: Position | D2: Monthly Salary($)
A3: 1 | B3: Qaali Daud Elmi | C3: Lead Interior Design
A4: 2 | B4: Abdinasir Shukri Adan | C4: Project Manager
A5: 3 | B5: Aweis Hassan Seyid | C5: Interior Design Officer
A6: 4 | B6: Mohamed Hassan | C6: Interior Design Assistance
A7: 5 | B7: Abdifatah Ibrahim | C7: Interior Design Assistance
A8: 6 | B8: Asia Ali Ahmed | C8: Admin and Finance Officer
A9: TOTAL PAYROLL | D9: =SUM(D3:D8) -> 0

Sheet 3. Project — A
A1: PROJECT EXPENSE SHEET — Project A
A2: Project Name: | B2: Project A
A3: Client:
A4: Client Payment ($): | B4: 0 | C4: Start Date:
B5: =D44 -> 0
A6: A. DESIGN COSTS
A7: Item | B7: Notes | D7: Cost ($)
A8: Site Visit | D8: 0
A9: 3D Design | D9: 0
A10: Printing Drawings | D10: 0
A11: Measurements | D11: 0
A12: DESIGN COSTS Sub-total | D12: =SUM(D8:D11) -> 0
A14: B. MATERIALS
A15: Item | B15: Qty / Days | C15: Unit Cost ($) | D15: Total Cost ($)
A16: Paint | B16: 0 | C16: 0 | D16: =B16*C16 -> 0
A17: Gypsum | B17: 0 | C17: 0 | D17: =B17*C17 -> 0
A18: Tiles | B18: 0 | C18: 0 | D18: =B18*C18 -> 0
A19: Lighting | B19: 0 | C19: 0 | D19: =B19*C19 -> 0
A20: Furniture | B20: 0 | C20: 0 | D20: =B20*C20 -> 0
B21: 0 | C21: 0 | D21: =B21*C21 -> 0
B22: 0 | C22: 0 | D22: =B22*C22 -> 0
A23: MATERIALS Sub-total | D23: =SUM(D16:D22) -> 0
A25: C. LABOUR COSTS
A26: Item | B26: Qty / Days | C26: Unit Cost ($) | D26: Total Cost ($)
A27: Carpenter | B27: 0 | C27: 0 | D27: =B27*C27 -> 0
A28: Painter | B28: 0 | C28: 0 | D28: =B28*C28 -> 0
A29: Electrician | B29: 0 | C29: 0 | D29: =B29*C29 -> 0
A30: Mason | B30: 0 | C30: 0 | D30: =B30*C30 -> 0
B31: 0 | C31: 0 | D31: =B31*C31 -> 0
A32: LABOUR COSTS Sub-total | D32: =SUM(D27:D31) -> 0
A34: D. SITE EXPENSES
A35: Item | B35: Notes | D35: Cost ($)
A36: Transport | D36: 0
A37: Fuel | D37: 0
A38: Food for Workers | D38: 0
A39: Equipment Rental | D39: 0
D40: 0
A41: SITE EXPENSES Sub-total | D41: =SUM(D36:D40) -> 0
A43: PROJECT SUMMARY
A44: Total Project Cost | D44: =D12+D23+D32+D41 -> 0
...

Sheet 4. Project — B
A1: PROJECT EXPENSE SHEET — Project B
A2: Project Name: | B2: Project B
A3: Client:
A4: Client Payment ($): | B4: 0 | C4: Start Date:
B5: =D44 -> 0
A6: A. DESIGN COSTS
A7: Item | B7: Notes | D7: Cost ($)
A8: Site Visit | D8: 0
A9: 3D Design | D9: 0
A10: Printing Drawings | D10: 0
A11: Measurements | D11: 0
A12: DESIGN COSTS Sub-total | D12: =SUM(D8:D11) -> 0
A14: B. MATERIALS
A15: Item | B15: Qty / Days | C15: Unit Cost ($) | D15: Total Cost ($)
A16: Paint | B16: 0 | C16: 0 | D16: =B16*C16 -> 0
A17: Gypsum | B17: 0 | C17: 0 | D17: =B17*C17 -> 0
A18: Tiles | B18: 0 | C18: 0 | D18: =B18*C18 -> 0
A19: Lighting | B19: 0 | C19: 0 | D19: =B19*C19 -> 0
A20: Furniture | B20: 0 | C20: 0 | D20: =B20*C20 -> 0
B21: 0 | C21: 0 | D21: =B21*C21 -> 0
B22: 0 | C22: 0 | D22: =B22*C22 -> 0
A23: MATERIALS Sub-total | D23: =SUM(D16:D22) -> 0
A25: C. LABOUR COSTS
A26: Item | B26: Qty / Days | C26: Unit Cost ($) | D26: Total Cost ($)
A27: Carpenter | B27: 0 | C27: 0 | D27: =B27*C27 -> 0
A28: Painter | B28: 0 | C28: 0 | D28: =B28*C28 -> 0
A29: Electrician | B29: 0 | C29: 0 | D29: =B29*C29 -> 0
A30: Mason | B30: 0 | C30: 0 | D30: =B30*C30 -> 0
B31: 0 | C31: 0 | D31: =B31*C31 -> 0
A32: LABOUR COSTS Sub-total | D32: =SUM(D27:D31) -> 0
A34: D. SITE EXPENSES
A35: Item | B35: Notes | D35: Cost ($)
A36: Transport | D36: 0
A37: Fuel | D37: 0
A38: Food for Workers | D38: 0
A39: Equipment Rental | D39: 0
D40: 0
A41: SITE EXPENSES Sub-total | D41: =SUM(D36:D40) -> 0
A43: PROJECT SUMMARY
A44: Total Project Cost | D44: =D12+D23+D32+D41 -> 0
...

Sheet 5. Project — C
A1: PROJECT EXPENSE SHEET — Project C
A2: Project Name: | B2: Project C
A3: Client:
A4: Client Payment ($): | B4: 0 | C4: Start Date:
B5: =D44 -> 0
A6: A. DESIGN COSTS
A7: Item | B7: Notes | D7: Cost ($)
A8: Site Visit | D8: 0
A9: 3D Design | D9: 0
A10: Printing Drawings | D10: 0
A11: Measurements | D11: 0
A12: DESIGN COSTS Sub-total | D12: =SUM(D8:D11) -> 0
A14: B. MATERIALS
A15: Item | B15: Qty / Days | C15: Unit Cost ($) | D15: Total Cost ($)
A16: Paint | B16: 0 | C16: 0 | D16: =B16*C16 -> 0
A17: Gypsum | B17: 0 | C17: 0 | D17: =B17*C17 -> 0
A18: Tiles | B18: 0 | C18: 0 | D18: =B18*C18 -> 0
A19: Lighting | B19: 0 | C19: 0 | D19: =B19*C19 -> 0
A20: Furniture | B20: 0 | C20: 0 | D20: =B20*C20 -> 0
B21: 0 | C21: 0 | D21: =B21*C21 -> 0
B22: 0 | C22: 0 | D22: =B22*C22 -> 0
A23: MATERIALS Sub-total | D23: =SUM(D16:D22) -> 0
A25: C. LABOUR COSTS
A26: Item | B26: Qty / Days | C26: Unit Cost ($) | D26: Total Cost ($)
A27: Carpenter | B27: 0 | C27: 0 | D27: =B27*C27 -> 0
A28: Painter | B28: 0 | C28: 0 | D28: =B28*C28 -> 0
A29: Electrician | B29: 0 | C29: 0 | D29: =B29*C29 -> 0
A30: Mason | B30: 0 | C30: 0 | D30: =B30*C30 -> 0
B31: 0 | C31: 0 | D31: =B31*C31 -> 0
A32: LABOUR COSTS Sub-total | D32: =SUM(D27:D31) -> 0
A34: D. SITE EXPENSES
A35: Item | B35: Notes | D35: Cost ($)
A36: Transport | D36: 0
A37: Fuel | D37: 0
A38: Food for Workers | D38: 0
A39: Equipment Rental | D39: 0
D40: 0
A41: SITE EXPENSES Sub-total | D41: =SUM(D36:D40) -> 0
A43: PROJECT SUMMARY
A44: Total Project Cost | D44: =D12+D23+D32+D41 -> 0
...
